<mujoco model="ur3e">
    <compiler angle="radian" meshdir="./mesh/ur3e/collision/" texturedir="./mesh/ur3e/visual/" />
    <!-- <option collision="predefined" /> -->

    <size njmax="500" nconmax="100" />
    <option timestep='0.001' gravity='0 0 -9.81'/>
    <default>
        <default class="force-torque">
        <site type="box" size=".01 .01 .02" rgba="1 0 0 1" />
      </default>
    </default>
    <visual>
        <headlight diffuse="0.6 0.6 0.6" ambient="0.3 0.3 0.3" specular="0 0 0" />
        <rgba haze="0.15 0.25 0.35 1" />
        <global offheight="2160" offwidth="3840"/>
        <quality offsamples="8"/>
    </visual>
    
    <asset>
        <mesh name="base"     file="base.stl" />
        <mesh name="shoulder" file="shoulder.stl" />
        <mesh name="upperarm" file="upperarm.stl" />
        <mesh name="forearm"  file="forearm.stl" />
        <mesh name="wrist1"   file="wrist1.stl" />
        <mesh name="wrist2"   file="wrist2.stl" />
        <mesh name="wrist3"   file="wrist3.stl" />


        <texture type="skybox" builtin="gradient" rgb1="0.3 0.5 0.7" rgb2="0 0 0" width="512" height="3072" />
        <texture type="2d" name="groundplane" builtin="checker" mark="edge" rgb1="0.2 0.3 0.4" rgb2="0.1 0.2 0.3" markrgb="0.8 0.8 0.8" width="300" height="300" />
        <material name="groundplane" texture="groundplane" texuniform="true" texrepeat="5 5" reflectance="0.5" />


    </asset>
    <worldbody>
    <body name="base" pos="0 0 0">
        <geom type="mesh" contype="0" conaffinity="0" group="1" rgba="0.7 0.7 0.7 1" mesh="base" />
        <geom type="mesh" rgba="0.7 0.7 0.7 1" mesh="base" />
        <body name="shoulder_link" pos="0 0 0.152">
            <inertial pos="0 0 0" mass="2" diaginertia="0.00809316 0.00809316 0.005625" />
            <joint name="shoulder_pan_joint" pos="0 0 0" axis="0 0 1" limited="true" range="-3.14159 3.14159" />
            <site name="shoulder_pan_sensor" class="force-torque"/>
            <geom type="mesh" contype="0" conaffinity="0" group="1" rgba="0.7 0.7 0.7 1" mesh="shoulder" />
            <geom type="mesh" rgba="0.7 0.7 0.7 1" mesh="shoulder" />
            <body name="upper_arm_link" pos="0 0.12 0" quat="0.707107 0 0.707107 0">
                <inertial pos="0 0 0.122" mass="3.42" diaginertia="0.0217771 0.0217771 0.00961875" />
                <joint name="shoulder_lift_joint" pos="0 0 0" axis="0 1 0" limited="true" range="-3.14159 3.14159" />
                <site name="shoulder_lift_sensor" class="force-torque"/>
                <geom type="mesh" contype="0" conaffinity="0" group="1" rgba="0.7 0.7 0.7 1" mesh="upperarm" />
                <geom type="mesh" rgba="0.7 0.7 0.7 1" mesh="upperarm" />
                <body name="forearm_link" pos="0 -0.093 0.244">
                    <inertial pos="0 0 0.1065" mass="1.26" diaginertia="0.00653562 0.00653562 0.00354375" />
                    <joint name="elbow_joint" pos="0 0 0" axis="0 1 0" limited="true" range="-3.14159 3.14159" />
                    <site name="elbow_sensor" class="force-torque"/>
                    <geom type="mesh" contype="0" conaffinity="0" group="1" rgba="0.7 0.7 0.7 1" mesh="forearm" />
                    <geom type="mesh" rgba="0.7 0.7 0.7 1" mesh="forearm" />
                    <body name="wrist_1_link" pos="0 0 0.213" quat="0.707107 0 0.707107 0">
                        <inertial pos="0 0 0" quat="0.5 0.5 -0.5 0.5" mass="0.8" diaginertia="0.00225 0.002085 0.002085" />
                        <joint name="wrist_1_joint" pos="0 0 0" axis="0 1 0" limited="true" range="-3.14159 3.14159" />
                        <site name="wrist_1_sensor" class="force-torque"/>
                        <geom type="mesh" contype="0" conaffinity="0" group="1" rgba="0.7 0.7 0.7 1" mesh="wrist1" />
                        <geom type="mesh" rgba="0.7 0.7 0.7 1" mesh="wrist1" />
                        <body name="wrist_2_link" pos="0 0.104 0">
                            <inertial pos="0 0 0" quat="0.5 0.5 -0.5 0.5" mass="0.8" diaginertia="0.00225 0.002085 0.002085" />
                            <joint name="wrist_2_joint" pos="0 0 0" axis="0 0 1" limited="true" range="-3.14159 3.14159" />
                            <site name="wrist_2_sensor" class="force-torque"/>
                            <geom type="mesh" contype="0" conaffinity="0" group="1" rgba="0.7 0.7 0.7 1" mesh="wrist2" />
                            <geom type="mesh" rgba="0.7 0.7 0.7 1" mesh="wrist2" />
                            <body name="wrist_3_link" pos="0 0 0.085">
                                <inertial pos="0 0.000233618 0" quat="0.5 0.5 -0.5 0.5" mass="0.351" diaginertia="0.000991097 0.000918909 0.000912204" />
                                <joint name="wrist_3_joint" pos="0 0 0" axis="0 1 0" limited="true" range="-3.14159 3.14159" />
                                <site name="wrist_3_sensor" class="force-torque"/>
                                <geom type="mesh" contype="0" conaffinity="0" group="1" rgba="0.7 0.7 0.7 1" mesh="wrist3" />
                                <geom type="mesh" rgba="0.7 0.7 0.7 1" mesh="wrist3" />
                                <geom size="0.005 0.005 0.005" pos="0 0.082 0" quat="0.707107 0 0 0.707107" type="box" />
                            </body>
                        </body>
                    </body>
                </body>
            </body>
        </body>
      </body>
    </worldbody>
    <!-- Actuators -->
    <actuator>
      <motor name="shoulder_pan_motor"  joint="shoulder_pan_joint"  ctrllimited="true" ctrlrange="-330 330" />
      <motor name="shoulder_lift_motor" joint="shoulder_lift_joint" ctrllimited="true" ctrlrange="-330 330" />
      <motor name="elbow_motor"         joint="elbow_joint"         ctrllimited="true" ctrlrange="-150 150" />
      <motor name="wrist_1_motor"       joint="wrist_1_joint"       ctrllimited="true" ctrlrange="-54 54" />
      <motor name="wrist_2_motor"       joint="wrist_2_joint"       ctrllimited="true" ctrlrange="-54 54" />
      <motor name="wrist_3_motor"       joint="wrist_3_joint"       ctrllimited="true" ctrlrange="-54 54" />
    </actuator>

    <sensor>
      <torque name="shoulder_lift_torque" site="shoulder_lift_sensor"/>
      <torque name="shoulder_pan_torque"  site="shoulder_pan_sensor" />
      <torque name="elbow_torque"         site="elbow_sensor"        />
      <torque name="wrist_1_torque"       site="wrist_1_sensor"      />
      <torque name="wrist_2_torque"       site="wrist_2_sensor"      />
      <torque name="wrist_3_torque"       site="wrist_3_sensor"      />

      <actuatorfrc name="shoulder_lift_actuatorfrc" actuator="shoulder_lift_motor"/>
      <actuatorfrc name="shoulder_pan_actuatorfrc"  actuator="shoulder_pan_motor" />
      <actuatorfrc name="elbow_actuatorfrc"         actuator="elbow_motor"        />
      <actuatorfrc name="wrist_1_actuatorfrc"       actuator="wrist_1_motor"      />
      <actuatorfrc name="wrist_2_actuatorfrc"       actuator="wrist_2_motor"      />
      <actuatorfrc name="wrist_3_actuatorfrc"       actuator="wrist_3_motor"      />
    </sensor>


</mujoco>
